ERROR 2025-03-25 18:15:52,221 error_handling 2691 6191820800 Error Response: 405 - {'detail': ErrorDetail(string='Method "GET" not allowed.', code='method_not_allowed')}
ERROR 2025-03-25 18:17:24,075 views 2737 6166114304 Task creation failed: The field 'assigned_users' was declared on serializer TaskSerializer, but has not been included in the 'fields' option.
Traceback (most recent call last):
  File "/Users/yashagrahari/Desktop/Josh-Backed-Task/task_management/tasks/views.py", line 23, in post
    serializer.is_valid(raise_exception=True)
    ~~~~~~~~~~~~~~~~~~~^^^^^^^^^^^^^^^^^^^^^^
  File "/Users/yashagrahari/Desktop/Josh-Backed-Task/venv/lib/python3.13/site-packages/rest_framework/serializers.py", line 223, in is_valid
    self._validated_data = self.run_validation(self.initial_data)
                           ~~~~~~~~~~~~~~~~~~~^^^^^^^^^^^^^^^^^^^
  File "/Users/yashagrahari/Desktop/Josh-Backed-Task/venv/lib/python3.13/site-packages/rest_framework/serializers.py", line 442, in run_validation
    value = self.to_internal_value(data)
  File "/Users/yashagrahari/Desktop/Josh-Backed-Task/venv/lib/python3.13/site-packages/rest_framework/serializers.py", line 495, in to_internal_value
    for field in fields:
                 ^^^^^^
  File "/Users/yashagrahari/Desktop/Josh-Backed-Task/venv/lib/python3.13/site-packages/rest_framework/serializers.py", line 378, in _writable_fields
    for field in self.fields.values():
                 ^^^^^^^^^^^
  File "/Users/yashagrahari/Desktop/Josh-Backed-Task/venv/lib/python3.13/site-packages/django/utils/functional.py", line 47, in __get__
    res = instance.__dict__[self.name] = self.func(instance)
                                         ~~~~~~~~~^^^^^^^^^^
  File "/Users/yashagrahari/Desktop/Josh-Backed-Task/venv/lib/python3.13/site-packages/rest_framework/serializers.py", line 372, in fields
    for key, value in self.get_fields().items():
                      ~~~~~~~~~~~~~~~^^
  File "/Users/yashagrahari/Desktop/Josh-Backed-Task/venv/lib/python3.13/site-packages/rest_framework/serializers.py", line 1079, in get_fields
    field_names = self.get_field_names(declared_fields, info)
  File "/Users/yashagrahari/Desktop/Josh-Backed-Task/venv/lib/python3.13/site-packages/rest_framework/serializers.py", line 1175, in get_field_names
    assert field_name in fields, (
           ^^^^^^^^^^^^^^^^^^^^
AssertionError: The field 'assigned_users' was declared on serializer TaskSerializer, but has not been included in the 'fields' option.
ERROR 2025-03-25 18:22:39,482 error_handling 2790 6124695552 Error Response: 405 - {'detail': ErrorDetail(string='Method "GET" not allowed.', code='method_not_allowed')}
ERROR 2025-03-25 18:22:46,141 views 2790 6124695552 Task assignment failed: The field 'assigned_users' was declared on serializer TaskSerializer, but has not been included in the 'fields' option.
Traceback (most recent call last):
  File "/Users/yashagrahari/Desktop/Josh-Backed-Task/task_management/tasks/views.py", line 55, in post
    return Response({'message': f'Task assigned to {len(users)} users', 'task': TaskSerializer(task).data}, status=status.HTTP_200_OK)
                                                                                ^^^^^^^^^^^^^^^^^^^^^^^^^
  File "/Users/yashagrahari/Desktop/Josh-Backed-Task/venv/lib/python3.13/site-packages/rest_framework/serializers.py", line 571, in data
    ret = super().data
          ^^^^^^^^^^^^
  File "/Users/yashagrahari/Desktop/Josh-Backed-Task/venv/lib/python3.13/site-packages/rest_framework/serializers.py", line 249, in data
    self._data = self.to_representation(self.instance)
                 ~~~~~~~~~~~~~~~~~~~~~~^^^^^^^^^^^^^^^
  File "/Users/yashagrahari/Desktop/Josh-Backed-Task/venv/lib/python3.13/site-packages/rest_framework/serializers.py", line 523, in to_representation
    for field in fields:
                 ^^^^^^
  File "/Users/yashagrahari/Desktop/Josh-Backed-Task/venv/lib/python3.13/site-packages/rest_framework/serializers.py", line 384, in _readable_fields
    for field in self.fields.values():
                 ^^^^^^^^^^^
  File "/Users/yashagrahari/Desktop/Josh-Backed-Task/venv/lib/python3.13/site-packages/django/utils/functional.py", line 47, in __get__
    res = instance.__dict__[self.name] = self.func(instance)
                                         ~~~~~~~~~^^^^^^^^^^
  File "/Users/yashagrahari/Desktop/Josh-Backed-Task/venv/lib/python3.13/site-packages/rest_framework/serializers.py", line 372, in fields
    for key, value in self.get_fields().items():
                      ~~~~~~~~~~~~~~~^^
  File "/Users/yashagrahari/Desktop/Josh-Backed-Task/venv/lib/python3.13/site-packages/rest_framework/serializers.py", line 1079, in get_fields
    field_names = self.get_field_names(declared_fields, info)
  File "/Users/yashagrahari/Desktop/Josh-Backed-Task/venv/lib/python3.13/site-packages/rest_framework/serializers.py", line 1175, in get_field_names
    assert field_name in fields, (
           ^^^^^^^^^^^^^^^^^^^^
AssertionError: The field 'assigned_users' was declared on serializer TaskSerializer, but has not been included in the 'fields' option.
